<!DOCTYPE html>
<html lang="en">

<head>
    <meta charset="UTF-8">
    <meta name="viewport" content="width=device-width, initial-scale=1.0">
    <title>Document</title>
</head>

<body>
    <script>
        const p1 = new Promise((resolve, reject) => {
            console.log("开始请求a数据");
            setTimeout(() => {
                try {
                    throw new Error("err:抛出错误");
                    console.log("a数据请求成功");
                    const userID = [1, 2, 3, 4];
                    resolve(userID);
                } catch (e) {
                    console.log("a数据请求失败");
                    reject(e);
                }

            }, 1000)
        })

        const p2 = p1.then((data) => {
            console.log(data);

        })
        const p3 = p2.catch((e) => { //是then返回失败promise对象调用的
            // console.log(e);
            // throw new Error("err:抛出错误");
            // return "hello"
            return new Promise((resolve, reject) => {
                reject(1);
            })
        })

        console.log(p3)

        /* 
            当一个失败的promise对象调用catch方法的话，就会进去catch执行

            当一个失败的promise对象调用then方法的时候，then方法不会执行里边的内容，而是直接返回一个失败的promise对象

            catch返回值的规则和then一样
         */
    </script>
</body>

</html>