<!DOCTYPE html>
<html lang="en">

<head>
    <meta charset="UTF-8">
    <meta name="viewport" content="width=device-width, initial-scale=1.0">
    <title>Document</title>
</head>

<body>
    <script>
        const p1 = new Promise((resolve, reject) => {
            console.log("开始请求a数据");
            setTimeout(() => {
                try {
                    throw new Error("err:抛出错误");
                    console.log("a数据请求成功");
                    const userID = [1, 2, 3, 4];
                    resolve(userID);
                } catch (e) {
                    console.log("a数据请求失败");
                    reject(e);
                }

            }, 1000)
        })

        const p2 = p1.then((data) => {
            console.log(data);

        })
        const p3 = p2.catch((e) => { //是then返回失败promise对象调用的
            console.log(e);
            return new Promise((resolve, reject) => {
                resolve("成功~")
                // reject("失败~")
            })
        })

        /* 
            无论是失败的还是成功的promise对象 都可以调用finally方法
            一般finally方法会放在promise调用的最后一步（不再调用了，所以不考虑返回值）
            finally的回调函数一般不书写参数，只是为了做最后一步操作

        */
        const p4 = p3.finally(() => {
            console.log();
        })

        console.log(p4)
    </script>
</body>

</html>